<?xml version="1.0"?>
<robot xmlns:xacro="http://ros.org/wiki/xacro">
  <!-- world 프레임은 절대 좌표계를 나타내며, 일반적으로 (0,0,0) 에서 시작. 정의하지 않더라도 시뮬레이션 환경이 기본적으로 제공 -->
  <link name="world"/>  
  <joint name="virtual_joint" type="fixed">
    <parent link="world"/>
    <child link="base_link"/>
    <!--<origin xyz="0.2 0.2 0.01" rpy="0 0 3.14"/>-->
    <origin xyz="0.0 0.0 0.01" rpy="0 0 0"/>
  </joint>

  <!-- ===== base_link ===== -->
  <link name="base_link">
    <visual>
      <geometry>
        <mesh filename="file://$(find ros2_control_demo_example_7)/meshes/visual/base_link.dae" />
      </geometry>
    </visual>
    <collision>
      <origin xyz="0 0 0" rpy="0 0 0" />
      <geometry>
        <mesh filename="file://$(find ros2_control_demo_example_7)/meshes/collision/base_link.STL" />
      </geometry>
    </collision>
    <inertial>
      <origin xyz="0.0001224 -0.008875 -0.00097063" rpy="0 0 0" />
      <mass value="0.96902" />
      <inertia
        ixx="0.0071925"
        ixy="6.8211E-06"
        ixz="-2.5763E-06"
        iyy="0.0012545"
        iyz="0.00018781"
        izz="0.0082011"/>
    </inertial>
  </link>

  <!-- ===== link_1 & joint_1 ===== -->
  <link name="link_1">
    <visual>
      <geometry>
        <mesh filename="file://$(find ros2_control_demo_example_7)/meshes/visual/link_1.dae" />
      </geometry>
    </visual>
    <collision>
      <geometry>
        <mesh filename="file://$(find ros2_control_demo_example_7)/meshes/collision/link_1.STL" />
      </geometry>
    </collision>
    <inertial>
      <origin xyz="-0.000609658597790607 0.00330590585718646 -0.00933034986379267" />
      <mass value="0.328947846694297" />
      <inertia
        ixx="0.00045094993717689"
        ixy="1.89811951102791E-06"
        ixz="3.525456008562E-06"
        iyy="0.00044481443653274"
        iyz="-2.29700773239265E-05"
        izz="0.000597809662084399" />
    </inertial>
  </link>
  <joint name="joint_1" type="revolute">
    <safety_controller k_position="100.0" k_velocity="40.0" soft_lower_limit="-1.5" soft_upper_limit="1.5" />
    <origin xyz="-1.1147E-05 -0.071734 0.0592" rpy="0 0 0" />
    <parent link="base_link" />
    <child link="link_1" />
    <axis xyz="0 0 1" />
    <limit lower="-1.57" upper="1.57" effort="100" velocity="1" />
    <dynamics damping="5.0" friction="1.0"/>
  </joint>

  <!-- ===== link_2 & joint_2 ===== -->
  <link name="link_2">
    <visual>
      <geometry>
        <mesh filename="file://$(find ros2_control_demo_example_7)/meshes/visual/link_2.dae" />
      </geometry>
    </visual>
    <collision>
      <geometry>
        <mesh filename="file://$(find ros2_control_demo_example_7)/meshes/collision/link_2.STL" />
      </geometry>
    </collision>
    <inertial>
      <origin xyz="-0.0288000000000148 6.00742142798727E-14 0.0519999999999917" />
      <mass value="0.0446134376029328" />
      <inertia
        ixx="4.05401757980631E-05"
        ixy="3.17637334559488E-22"
        ixz="2.01367711623734E-20"
        iyy="6.55761730829189E-05"
        iyz="-1.94385167769473E-21"
        izz="2.97446545917081E-05" />
    </inertial>
  </link>
  <joint name="joint_2" type="revolute">
    <safety_controller k_position="100.0" k_velocity="40.0" soft_lower_limit="-1.5" soft_upper_limit="1.5" />
    <origin xyz="0.0288 0 0.013" rpy="0 0 0" />
    <parent link="link_1" />
    <child link="link_2" />
    <axis xyz="-1 0 0" />
    <limit lower="-1.57" upper="1.57" effort="100" velocity="1" />
    <dynamics damping="5.0" friction="1.0"/>
  </joint>

  <!-- ===== link_3 & joint_3 ===== -->
  <link name="link_3">
    <visual>
      <geometry>
        <mesh filename="file://$(find ros2_control_demo_example_7)/meshes/visual/link_3.dae" />
      </geometry>
    </visual>
    <collision>
      <geometry>
        <mesh filename="file://$(find ros2_control_demo_example_7)/meshes/collision/link_3.STL" />
      </geometry>
    </collision>
    <inertial>
      <origin xyz="-0.0286220120797086 -0.001175733216222 0.0392749999999918" />
      <mass value="0.220136721586207" />
      <inertia
        ixx="0.000235043102755768"
        ixy="-1.43403053131161E-06"
        ixz="1.13252955862252E-19"
        iyy="0.000262566063435836"
        iyz="-6.04471436443364E-19"
        izz="4.63707847937597E-05" />
    </inertial>
  </link>
  <joint name="joint_3" type="revolute">
    <safety_controller k_position="100.0" k_velocity="40.0" soft_lower_limit="-1.5" soft_upper_limit="1.5" />
    <origin xyz="-0.002 0 0.104" rpy="0 0 0" />
    <parent link="link_2" />
    <child link="link_3" />
    <axis xyz="-1 0 0" />
    <limit lower="-1.57" upper="1.57" effort="100" velocity="1" />
    <dynamics damping="0.5" friction="0.1"/>
  </joint>

  <!-- ===== link_4 & joint_4 ===== -->
  <link name="link_4">
    <visual>
      <geometry>
        <mesh filename="file://$(find ros2_control_demo_example_7)/meshes/visual/link_4.dae" />
      </geometry>
    </visual>
    <collision>
      <geometry>
        <mesh filename="file://$(find ros2_control_demo_example_7)/meshes/collision/link_4.STL" />
      </geometry>
    </collision>
    <inertial>
      <origin xyz="-0.0297774697183034 -0.00821390272175576 0.0687270935087147" />
      <mass value="0.132393899698309" />
      <inertia
        ixx="8.71651655946543E-05"
        ixy="-2.50552338787903E-07"
        ixz="2.8603594687542E-07"
        iyy="8.49060105958196E-05"
        iyz="7.84914917087442E-06"
        izz="3.91241827118605E-05" />
    </inertial>
  </link>
  <joint name="joint_4" type="revolute">
    <safety_controller k_position="100.0" k_velocity="40.0" soft_lower_limit="0" soft_upper_limit="3.1" />
    <origin xyz="0.002 0 0.07855" rpy="1.5708 0 0" />
    <parent link="link_3" />
    <child link="link_4" />
    <axis xyz="-1 0 0" />
    <!--원래 lower 0, moveit에서 부동소수점 오류때문에 수정 -->
    <limit lower="0.0" upper="3.14" effort="100" velocity="1" />
    <dynamics damping="0.5" friction="0.1"/>
  </joint>

  <!-- ===== handlink_1 & joint_5 ===== -->
  <link name="link_5">
    <visual>
      <geometry>
        <mesh filename="file://$(find ros2_control_demo_example_7)/meshes/visual/link_5.dae" />
      </geometry>
    </visual>
    <collision>
      <geometry>
        <mesh filename="file://$(find ros2_control_demo_example_7)/meshes/collision/link_5.STL" />
      </geometry>
    </collision>
    <inertial>
      <origin xyz="-0.0212995941604227 -0.0189419547084066 0.0311529603124066" />
      <mass value="0.109476145966328" />
      <inertia
        ixx="2.8150279625261E-05"
        ixy="-6.01204162152963E-06"
        ixz="1.94732192852111E-06"
        iyy="2.96177247143144E-05"
        iyz="1.74075431085897E-06"
        izz="4.32724706664679E-05" />
    </inertial>
  </link>
  <joint name="joint_5" type="revolute">
    <safety_controller k_position="100.0" k_velocity="40.0" soft_lower_limit="-1.5" soft_upper_limit="1.5" />
    <origin xyz="-0.0288 0 0.1051" rpy="0 0 0" />
    <parent link="link_4" />
    <child link="link_5" />
    <axis xyz="0 0 -1" />
    <limit lower="-1.57" upper="1.57" effort="100" velocity="1" />
    <dynamics damping="0.5" friction="0.1"/>
  </joint>

  <!-- ===== handlink_2 & jointhand_1 ===== -->
  <link name="handlink_1">
    <visual>
      <geometry>
        <mesh filename="file://$(find ros2_control_demo_example_7)/meshes/visual/handlink_1.dae" />
      </geometry>
    </visual>
    <collision>
      <geometry>
        <mesh filename="file://$(find ros2_control_demo_example_7)/meshes/collision/handlink_1.STL" />
      </geometry>
    </collision>
    <inertial>
      <origin xyz="1.91302595857479E-06 -0.00124999999999997 0.00659111702735025" />
      <mass value="0.00398580770176869" />
      <inertia
        ixx="5.75743202308589E-07"
        ixy="-4.10766755623607E-23"
        ixz="-9.24514874080794E-11"
        iyy="6.89575574391505E-07"
        iyz="1.53560939821316E-22"
        izz="1.17984255105591E-07" />
    </inertial>
  </link>
  <joint name="jointhand_1" type="revolute">
    <safety_controller k_position="100.0" k_velocity="40.0" soft_lower_limit="-1.5" soft_upper_limit="1.5" />
    <origin xyz="-0.014 0.0065 0.032" rpy="0 -0.5236 0" />
    <parent link="link_5" />
    <child link="handlink_1" />
    <axis xyz="0 -1 0" />
    <limit lower="-1.57" upper="1.57" effort="100" velocity="1" />
    <dynamics damping="0.5" friction="0.1"/>
  </joint>

  <!-- ===== handlink_2 & jointhand_2 (mimic=jointhand_1) ===== -->
  <link name="handlink_2">
    <visual>
      <geometry>
        <mesh filename="file://$(find ros2_control_demo_example_7)/meshes/visual/handlink_2.dae" />
      </geometry>
    </visual>
    <collision>
      <geometry>
        <mesh filename="file://$(find ros2_control_demo_example_7)/meshes/collision/handlink_2.STL" />
      </geometry>
    </collision>
    <inertial>
      <origin xyz="-1.91302594651499E-06 -0.00124999999999997 0.00659111702735596" />
      <mass value="0.00398580770176871" />
      <inertia
        ixx="5.75743202308592E-07"
        ixy="-3.65809007719365E-23"
        ixz="9.24514874082316E-11"
        iyy="6.8957557439151E-07"
        iyz="2.61481119429676E-22"
        izz="1.17984255105593E-07" />
    </inertial>
  </link>
  <joint name="jointhand_2" type="revolute">
    <safety_controller k_position="100.0" k_velocity="40.0" soft_lower_limit="-1.5" soft_upper_limit="1.5" />
    <origin xyz="0.014 0.0065 0.032" rpy="0 0.5236 0" />
    <parent link="link_5" />
    <child link="handlink_2" />
    <axis xyz="0 -1 0" />
    <limit lower="-1.57" upper="1.57" effort="100" velocity="1" />
    <!-- Here we mimic jointhand_1 -->
    <mimic joint="jointhand_1" multiplier="-1" offset="0" />
    <dynamics damping="0.5" friction="0.1"/>
  </joint>

  <!-- ===== handlink_3 & jointhand_3 (mimic=jointhand_1) ===== -->
  <link name="handlink_3">
    <visual>
      <geometry>
        <mesh filename="file://$(find ros2_control_demo_example_7)/meshes/visual/handlink_3.dae" />
      </geometry>
    </visual>
    <collision>
      <geometry>
        <mesh filename="file://$(find ros2_control_demo_example_7)/meshes/collision/handlink_3.STL" />
      </geometry>
    </collision>
    <inertial>
      <origin xyz="-0.00763735753923525 -0.0129517685330851 -0.00275000000000003" />
      <mass value="0.00166444867208552" />
      <inertia
        ixx="1.65921841786484E-07"
        ixy="-8.09245865835559E-08"
        ixz="7.86240296925019E-22"
        iyy="7.64057024757358E-08"
        iyz="1.48393808362868E-21"
        izz="1.89826186055393E-07" />
    </inertial>
  </link>
  <joint name="jointhand_3" type="revolute">
    <safety_controller k_position="100.0" k_velocity="40.0" soft_lower_limit="-1.5" soft_upper_limit="1.5" />
    <origin xyz="-0.0062319 0.004 0.052" rpy="-1.5708 0 0" />
    <parent link="link_5" />
    <child link="handlink_3" />
    <axis xyz="0 0 -1" />
    <limit lower="-1.57" upper="1.57" effort="100" velocity="1" />
    <mimic joint="jointhand_1" multiplier="1" offset="0" />
    <dynamics damping="0.5" friction="0.1"/>
  </joint>

  <!-- ===== handlink_4 & jointhand_4 (mimic=jointhand_1) ===== -->
  <link name="handlink_4">
    <visual>
      <geometry>
        <mesh filename="file://$(find ros2_control_demo_example_7)/meshes/visual/handlink_4.dae" />
      </geometry>
    </visual>
    <collision>
      <geometry>
        <mesh filename="file://$(find ros2_control_demo_example_7)/meshes/collision/handlink_4.STL" />
      </geometry>
    </collision>
    <inertial>
      <origin xyz="0.00763735753899841 -0.0129517685330592 -0.00274999999999975" rpy="0 0 0" />
      <mass value="0.00166444867208552" />
      <inertia
        ixx="1.65921841785793E-07"
        ixy="8.09245865839385E-08"
        ixz="-5.25249334069242E-22"
        iyy="7.64057024764273E-08"
        iyz="4.48254790926745E-22"
        izz="1.89826186055393E-07" />
    </inertial>
  </link>
  <joint name="jointhand_4" type="revolute">
    <safety_controller k_position="100.0" k_velocity="40.0" soft_lower_limit="-1.5" soft_upper_limit="1.5" />
    <origin xyz="0.0062319 0.004 0.052" rpy="-1.5708 0 0" />
    <parent link="link_5" />
    <child link="handlink_4" />
    <axis xyz="0 0 -1" />
    <limit lower="-1.57" upper="1.57" effort="100" velocity="1" />
    <mimic joint="jointhand_1" multiplier="-1" offset="0" />
    <dynamics damping="0.5" friction="0.1"/>
  </joint>

  <!-- ===== handlink_5 & jointhand_5 (mimic=jointhand_1) ===== -->
  <link name="handlink_5">
    <visual>
      <geometry>
        <mesh filename="file://$(find ros2_control_demo_example_7)/meshes/visual/handlink_5.dae" />
      </geometry>
    </visual>
    <collision>
      <geometry>
        <mesh filename="file://$(find ros2_control_demo_example_7)/meshes/collision/handlink_5.STL" />
      </geometry>
    </collision>
    <inertial>
      <origin xyz="-0.002176906577616 -0.0025 0.0197718141150072" />
      <mass value="0.00540491979787455" />
      <inertia
        ixx="1.38362372103744E-06"
        ixy="3.15445699744897E-22"
        ixz="2.47721674313908E-07"
        iyy="1.46051786734624E-06"
        iyz="-1.77861678727195E-21"
        izz="9.94146454666123E-08" />
    </inertial>
  </link>
  <joint name="jointhand_5" type="revolute">
    <safety_controller k_position="100.0" k_velocity="40.0" soft_lower_limit="-1.5" soft_upper_limit="1.5" />
    <origin xyz="-0.00015981 -0.0025 0.031" rpy="0 0.88992 0" />
    <parent link="handlink_1" />
    <child link="handlink_5" />
    <axis xyz="0 -1 0" />
    <limit lower="-1.57" upper="1.57" effort="100" velocity="1" />
    <mimic joint="jointhand_1" multiplier="-1" offset="0" />
    <dynamics damping="0.5" friction="0.1"/>
  </joint>

  <!-- ===== handlink_6 & jointhand_6 (mimic=jointhand_1) ===== -->
  <link name="handlink_6">
    <visual>
      <geometry>
        <mesh filename="file://$(find ros2_control_demo_example_7)/meshes/visual/handlink_6.dae" />
      </geometry>
    </visual>
    <collision>
      <geometry>
        <mesh filename="file://$(find ros2_control_demo_example_7)/meshes/collision/handlink_6.STL" />
      </geometry>
    </collision>
    <inertial>
      <origin xyz="0.00217690657761602 -0.00250000000000006 0.0197718141150072" rpy="0 0 0" />
      <mass value="0.00540491979787456" />
      <inertia
        ixx="1.38362372103744E-06"
        ixy="2.11126980545338E-22"
        ixz="-2.47721674313907E-07"
        iyy="1.46051786734624E-06"
        iyz="9.86615744254017E-22"
        izz="9.94146454666123E-08" />
    </inertial>
  </link>
  <joint name="jointhand_6" type="revolute">
    <safety_controller k_position="100.0" k_velocity="40.0" soft_lower_limit="-1.5" soft_upper_limit="1.5" />
    <origin xyz="0.00015981 -0.0025 0.031" rpy="0 -0.88992 0" />
    <parent link="handlink_2" />
    <child link="handlink_6" />
    <axis xyz="0 1 0" />
    <limit lower="-1.57" upper="1.57" effort="100" velocity="1" />
    <mimic joint="jointhand_1" multiplier="-1" offset="0" />
    <dynamics damping="0.5" friction="0.1"/>
  </joint>


</robot>
